### 异常处理

> 在 Go 语言中，程序中一般是使用错误来处理异常情况。对于程序中出现的大部分异常情况，错误就已经够用了。但在有些情况，当程序发生异常时，无法继续运行。在这种情况下，我们会使用 panic 来终止程序。当函数发生 panic 时，它会终止运行，在执行完所有的延迟函数后，程序控制返回到该函数的调用方。这样的过程会一直持续下去，直到当前协程的所有函数都返回退出，然后程序会打印出 panic 信息，接着打印出堆栈跟踪（Stack Trace），最后程序终止

#### panic的运用

> 需要注意的是，你应该尽可能地使用错误，而不是使用 panic 和 recover。只有当程序不能继续运行的时候，才应该使用 panic 和 recover 机制。

> panic的使用场景：<br/>
> 发生了一个不能恢复的错误，此时程序不能继续运行。 一个例子就是 web 服务器无法绑定所要求的端口。在这种情况下，就应该使用 panic，因为如果不能绑定端口，啥也做不了。<br>
> 发生了一个编程上的错误。 假如我们有一个接收指针参数的方法，而其他人使用 nil 作为参数调用了它。在这种情况下，我们可以使用 panic，因为这是一个编程错误：用 nil 参数调用了一个只能接收合法指针的方法。



#### 发生panic时的defer

> 当函数发生 panic 时，它会终止运行，在执行完所有的延迟函数后，程序控制返回到该函数的调用方。这样的过程会一直持续下去，直到当前协程的所有函数都返回退出，然后程序会打印出 panic 信息，接着打印出堆栈跟踪，最后程序终止。


```go
package main

import (  
    "fmt"
)

func fullName(firstName *string, lastName *string) {  
    defer fmt.Println("deferred call in fullName")
    if firstName == nil {
        panic("runtime error: first name cannot be nil")
    }
    if lastName == nil {
        panic("runtime error: last name cannot be nil")
    }
    fmt.Printf("%s %s\n", *firstName, *lastName)
    fmt.Println("returned normally from fullName")
}

func main() {  
    defer fmt.Println("deferred call in main")
    firstName := "Elon"
    fullName(&firstName, nil)
    fmt.Println("returned normally from main")
}
```


#### recover

> recover是一个内建函数，用于重新获得panic协程的控制。

```go
func recover() interface{}
```

> 捕获panic的异常

```go
package main

import (  
    "fmt"
)

func recoverName() {  
    if r := recover(); r!= nil {
        fmt.Println("recovered from ", r)
    }
}

func fullName(firstName *string, lastName *string) {  
    defer recoverName()
    if firstName == nil {
        panic("runtime error: first name cannot be nil")
    }
    if lastName == nil {
        panic("runtime error: last name cannot be nil")
    }
    fmt.Printf("%s %s\n", *firstName, *lastName)
    fmt.Println("returned normally from fullName")
}

func main() {  
    defer fmt.Println("deferred call in main")
    firstName := "Elon"
    fullName(&firstName, nil)
    fmt.Println("returned normally from main")
}
```

#### panic、recover和go协程

> 只有在相同的 Go 协程中调用 recover 才管用。recover 不能恢复一个不同协程的 panic。

```go
package main

import (  
    "fmt"
    "time"
)

func recovery() {  
    if r := recover(); r != nil {
        fmt.Println("recovered:", r)
    }
}

func a() {  
    defer recovery()
    fmt.Println("Inside A")
    go b()
    time.Sleep(1 * time.Second)
}

func b() {  
    fmt.Println("Inside B")
    panic("oh! B panicked")
}

func main() {  
    a()
    fmt.Println("normally returned from main")
}
```

> panic 并不会恢复。因为调用 recovery 的协程和 b() 中发生 panic 的协程并不相同，因此不可能恢复 panic。


#### 获取后获取堆栈跟踪

```go
package main

import (  
    "fmt"
    "runtime/debug"
)

func r() {  
    if r := recover(); r != nil {
        fmt.Println("Recovered", r)
        debug.PrintStack()
    }
}

func a() {  
    defer r()
    n := []int{5, 7, 4}
    fmt.Println(n[3])
    fmt.Println("normally returned from a")
}

func main() {  
    a()
    fmt.Println("normally returned from main")
}
```